When updating iam user path attrib on existing user with boto3.resource('iam').User.
The update completes successfully but boto3 throws exception when building the
'empty' response:

awsorgs.utils: DEBUG    manage_local_user_in_accounts():  account: ashley-training, local user exists: arn:aws:iam::071826132890:user/awsauth/service/ca/eoc-monitor-test
Exception in thread Thread-45:
Traceback (most recent call last):
  File "/usr/local/lib/python3.6/threading.py", line 916, in _bootstrap_inner
    self.run()
  File "/usr/local/lib/python3.6/threading.py", line 864, in run
    self._target(*self._args, **self._kwargs)
  File "/home/agould/git-repos/github/ashleygould/aws-orgs/awsorgs/utils.py", line 244, in worker
    func(item, *args)
  File "/home/agould/git-repos/github/ashleygould/aws-orgs/awsorgs/auth.py", line 653, in manage_local_user_in_accounts
    user = user.update(NewPath=path_spec)
  File "/home/agould/python-venv/python3.6/lib/python3.6/site-packages/boto3/resources/factory.py", line 520, in do_action
    response = action(self, *args, **kwargs)
  File "/home/agould/python-venv/python3.6/lib/python3.6/site-packages/boto3/resources/action.py", line 87, in __call__
    return self._response_handler(parent, params, response)
  File "/home/agould/python-venv/python3.6/lib/python3.6/site-packages/boto3/resources/response.py", line 263, in __call__
    self.service_context.service_model)
  File "/home/agould/python-venv/python3.6/lib/python3.6/site-packages/boto3/resources/response.py", line 118, in build_empty_response
    if shape.type_name == 'structure':
AttributeError: 'NoneType' object has no attribute 'type_name'

awsorgs.utils: DEBUG    manage_local_user_in_accounts():  account: segConf, local user exists: arn:aws:iam::737379256701:user/awsauth/service/ca/eoc-monitor-test
^CT
